<?xml version='1.0'?>

<!-- Per the bug described here: https://bitbucket.org/osrf/sdformat/issues/132/parser-does-not-handle-urdf-material, the name attribute was removed from tags.
This allows colors to be applied to the links -->


<robot name="my_robot" xmlns:xacro="http://www.ros.org/wiki/xacro">

  <xacro:include filename="$(find my_robot)/urdf/my_robot.gazebo" />

  <link name="robot_footprint"></link>

  <joint name="robot_footprint_joint" type="fixed">
    <origin xyz="0 0 0" rpy="0 0 0" />
    <parent link="robot_footprint"/>
    <child link="chassis" />
  </joint>

  <link name='chassis'>
    <pose>0 0 0.1 0 0 0</pose>

    <inertial>
      <mass value="15.0"/>
      <origin xyz="0.0 0 0" rpy=" 0 0 0"/>
      <inertia
          ixx="0.1" ixy="0" ixz="0"
          iyy="0.1" iyz="0"
          izz="0.1"
      />
    </inertial>

    <collision name='chassis_bottom'>
      <origin xyz="0 0 0" rpy=" 0 0 0"/> 
      <geometry>
        <box size=".4 .3 .05"/>
      </geometry>
    </collision>

    <!--  name='chassis_bottom_visual' -->
    <visual>
      <origin xyz="0 0 0" rpy=" 0 0 0"/>
      <geometry>
        <box size=".4 .3 .05"/>
      </geometry> 
    </visual>

    <collision name='chassis_top'>
      <origin xyz="0 0 0.2" rpy=" 0 0 0"/> 
      <geometry>
        <box size=".4 .3 .05"/>
      </geometry>
    </collision>

    <!--  name='chassis_top_visual' -->
    <visual>
      <origin xyz="0 0 0.2" rpy=" 0 0 0"/> 
      <geometry>
        <box size=".4 .3 .05"/>
      </geometry>
    </visual>

    <!-- Support posts -->

    <!--  name='post_FL_visual' -->
    <visual>
      <origin xyz="0.18 0.13 0.1" rpy=" 0 0 0"/> 
      <geometry>
        <cylinder length="0.2" radius="0.01"/>
      </geometry>
    </visual>

    <!--  name='post_FR_visual' -->
    <visual>
      <origin xyz="0.18 -0.13 0.1" rpy=" 0 0 0"/> 
      <geometry>
        <cylinder length="0.2" radius="0.01"/>
      </geometry>
    </visual>

    <!--  name='post_BL_visual' -->
    <visual>
      <origin xyz="-0.18 0.13 0.1" rpy=" 0 0 0"/> 
      <geometry>
        <cylinder length="0.2" radius="0.01"/>
      </geometry>
    </visual>

    <!--  name='post_BR_visual' -->
    <visual>
      <origin xyz="-0.18 -0.13 0.1" rpy=" 0 0 0"/> 
      <geometry>
        <cylinder length="0.2" radius="0.01"/>
      </geometry>
    </visual>

    <collision name='posts_collision'>
      <origin xyz="0 0 0.1" rpy=" 0 0 0"/> 
      <geometry>
        <box size=".4 .3 .2"/>
      </geometry>
    </collision>    


    <!-- camera mount -->

    <!--  name='camera_mount_visual' -->
    <visual>
      <origin xyz="0.17 0 0.055" rpy=" 0 0 0"/> 
      <geometry>
        <box size=".01 .06 .06"/>
      </geometry>
    </visual>

    <!-- casters -->

    <collision name='back_caster_collision'>
      <origin xyz="-0.15 0 -0.05" rpy=" 0 0 0"/>
      <geometry>
        <sphere radius="0.0499"/>
      </geometry>
    </collision>

    <!--  name='back_caster_visual' -->
    <visual name='back_caster_visual'>
      <origin xyz="-0.15 0 -0.05" rpy=" 0 0 0"/>
      <geometry>
        <sphere radius="0.05"/>
      </geometry>
    </visual>

    <collision name='front_caster_collision'>
      <origin xyz="0.15 0 -0.05" rpy=" 0 0 0"/>
      <geometry>
        <sphere radius="0.0499"/>
      </geometry>
    </collision>

    <!--  name='front_caster_visual' -->
    <visual name='front_caster_visual'>
      <origin xyz="0.15 0 -0.05" rpy=" 0 0 0"/>
      <geometry>
        <sphere radius="0.05"/>
      </geometry>
    </visual>

  </link>

  <!-- wheels -->

  <link name='left_wheel'>

    <inertial>
      <mass value="5.0"/>
      <origin xyz="0 0 0" rpy=" 0 1.5707 1.5707"/>
      <inertia
          ixx="0.1" ixy="0" ixz="0"
          iyy="0.1" iyz="0"
          izz="0.1"
      />
    </inertial>

    <collision name='left_wheel_collision'>
      <origin xyz="0 0 0" rpy=" 0 1.5707 1.5707"/> 
      <geometry>
        <cylinder length="0.05" radius="0.1"/>
      </geometry>
    </collision>

    <visual name='left_wheel_visual'>
      <origin xyz="0 0 0" rpy=" 0 1.5707 1.5707"/>
      <geometry>
        <cylinder length="0.05" radius="0.1"/>
      </geometry>
    </visual>

  </link>

  <link name='right_wheel'>

    <inertial>
      <mass value="5.0"/>
      <origin xyz="0 0 0" rpy=" 0 1.5707 1.5707"/>
      <inertia
          ixx="0.1" ixy="0" ixz="0"
          iyy="0.1" iyz="0"
          izz="0.1"
      />
    </inertial>

    <collision name='right_wheel_collision'>
      <origin xyz="0 0 0" rpy=" 0 1.5707 1.5707"/> 
      <geometry>
        <cylinder length="0.05" radius="0.1"/>
      </geometry>
    </collision>

    <visual name='right_wheel_visual'>
      <origin xyz="0 0 0" rpy=" 0 1.5707 1.5707"/>
      <geometry>
        <cylinder length="0.05" radius="0.1"/>
      </geometry>
    </visual>

  </link>

 <!-- Sensors -->

  <link name='camera'>

    <inertial>
      <mass value="0.1"/>
      <origin xyz="0 0 0" rpy=" 0 0 0"/>
      <inertia
          ixx="1e-6" ixy="0" ixz="0"
          iyy="1e-6" iyz="0"
          izz="1e-6"
      />
    </inertial>

    <collision name='camera_collision'>
      <origin xyz="0 0 0" rpy=" 0 0 0"/> 
      <geometry>
        <box size=".05 .05 .05"/>
      </geometry>
    </collision>

    <visual name='camera_visual'>
      <origin xyz="0 0 0" rpy=" 0 0 0"/>
      <geometry>
        <box size=".05 .05 .05"/>
      </geometry>
    </visual>

    <box_inertia sizeX="0.05" sizeY="0.05" sizeZ="0.05" mass="0.1">
      <origin xyz="0 0 0" rpy="0 0 0" />
    </box_inertia>

  </link>

  <link name='hokuyo'>

    <inertial>
      <mass value="1e-5"/>
      <origin xyz="0 0 0" rpy=" 0 0 0"/>
      <inertia
          ixx="1e-6" ixy="0" ixz="0"
          iyy="1e-6" iyz="0"
          izz="1e-6"
      />
    </inertial>

    <collision name='hokuyo_collision'>
      <origin xyz="0 0 0" rpy=" 0 0 0"/> 
      <geometry>
        <box size=".1 .1 .1"/>
      </geometry>
    </collision>

    <visual name='hokuyo_visual'>
      <origin xyz="0 0 0" rpy=" 0 0 0"/>
      <geometry>
        <mesh filename="package://my_robot/meshes/hokuyo.dae"/>
      </geometry>
    </visual>

  </link>

   <joint type="continuous" name="left_wheel_hinge">
    <origin xyz="0 0.18 0" rpy="0 0 0"/>
    <child link="left_wheel"/>
    <parent link="chassis"/>
    <axis xyz="0 1 0" rpy="0 0 0"/>
    <limit effort="10000" velocity="1000"/>
    <dynamics damping="1.0" friction="1.0"/>
  </joint>

   <joint type="continuous" name="right_wheel_hinge">
    <origin xyz="0 -0.18 0" rpy="0 0 0"/>
    <child link="right_wheel"/>
    <parent link="chassis"/>
    <axis xyz="0 1 0" rpy="0 0 0"/>
    <limit effort="10000" velocity="1000"/>
    <dynamics damping="1.0" friction="1.0"/>
  </joint>

   <joint type="fixed" name="camera_joint">
    <origin xyz="0.2 0 0.055" rpy="0 0 0"/>
    <child link="camera"/>
    <parent link="chassis"/>
    <axis xyz="0 1 0" rpy="0 0 0"/>
  </joint>

   <joint type="fixed" name="hokuyo_joint">
    <origin xyz="0.15 0 0.26" rpy="0 0 0"/>
    <child link="hokuyo"/>
    <parent link="chassis"/>
    <axis xyz="0 1 0" rpy="0 0 0"/>
  </joint>

  <gazebo reference="left_wheel">
    <material>Gazebo/Green</material>
  </gazebo>

  <gazebo reference="right_wheel">
    <material>Gazebo/Green</material>
  </gazebo>

  <gazebo reference="chassis">
    <material>Gazebo/Blue</material>
  </gazebo>

  <gazebo reference="camera">
    <material>Gazebo/Red</material>
  </gazebo>

</robot>
